ERROR:root:code for hash md5 was not found.
Traceback (most recent call last):
  File "/usr/local/Cellar/python@2/2.7.15_1/Frameworks/Python.framework/Versions/2.7/lib/python2.7/hashlib.py", line 147, in <module>
    globals()[__func_name] = __get_hash(__func_name)
  File "/usr/local/Cellar/python@2/2.7.15_1/Frameworks/Python.framework/Versions/2.7/lib/python2.7/hashlib.py", line 97, in __get_builtin_constructor
    raise ValueError('unsupported hash type ' + name)
ValueError: unsupported hash type md5
ERROR:root:code for hash sha1 was not found.
Traceback (most recent call last):
  File "/usr/local/Cellar/python@2/2.7.15_1/Frameworks/Python.framework/Versions/2.7/lib/python2.7/hashlib.py", line 147, in <module>
    globals()[__func_name] = __get_hash(__func_name)
  File "/usr/local/Cellar/python@2/2.7.15_1/Frameworks/Python.framework/Versions/2.7/lib/python2.7/hashlib.py", line 97, in __get_builtin_constructor
    raise ValueError('unsupported hash type ' + name)
ValueError: unsupported hash type sha1
ERROR:root:code for hash sha224 was not found.
Traceback (most recent call last):
  File "/usr/local/Cellar/python@2/2.7.15_1/Frameworks/Python.framework/Versions/2.7/lib/python2.7/hashlib.py", line 147, in <module>
    globals()[__func_name] = __get_hash(__func_name)
  File "/usr/local/Cellar/python@2/2.7.15_1/Frameworks/Python.framework/Versions/2.7/lib/python2.7/hashlib.py", line 97, in __get_builtin_constructor
    raise ValueError('unsupported hash type ' + name)
ValueError: unsupported hash type sha224
ERROR:root:code for hash sha256 was not found.
Traceback (most recent call last):
  File "/usr/local/Cellar/python@2/2.7.15_1/Frameworks/Python.framework/Versions/2.7/lib/python2.7/hashlib.py", line 147, in <module>
    globals()[__func_name] = __get_hash(__func_name)
  File "/usr/local/Cellar/python@2/2.7.15_1/Frameworks/Python.framework/Versions/2.7/lib/python2.7/hashlib.py", line 97, in __get_builtin_constructor
    raise ValueError('unsupported hash type ' + name)
ValueError: unsupported hash type sha256
ERROR:root:code for hash sha384 was not found.
Traceback (most recent call last):
  File "/usr/local/Cellar/python@2/2.7.15_1/Frameworks/Python.framework/Versions/2.7/lib/python2.7/hashlib.py", line 147, in <module>
    globals()[__func_name] = __get_hash(__func_name)
  File "/usr/local/Cellar/python@2/2.7.15_1/Frameworks/Python.framework/Versions/2.7/lib/python2.7/hashlib.py", line 97, in __get_builtin_constructor
    raise ValueError('unsupported hash type ' + name)
ValueError: unsupported hash type sha384
ERROR:root:code for hash sha512 was not found.
Traceback (most recent call last):
  File "/usr/local/Cellar/python@2/2.7.15_1/Frameworks/Python.framework/Versions/2.7/lib/python2.7/hashlib.py", line 147, in <module>
    globals()[__func_name] = __get_hash(__func_name)
  File "/usr/local/Cellar/python@2/2.7.15_1/Frameworks/Python.framework/Versions/2.7/lib/python2.7/hashlib.py", line 97, in __get_builtin_constructor
    raise ValueError('unsupported hash type ' + name)
ValueError: unsupported hash type sha512
/usr/local/lib/python2.7/site-packages/agate/utils.py:292: DuplicateColumnWarning: Column name "Num" already exists in Table. Column will be renamed to "Num_2".
/usr/local/lib/python2.7/site-packages/agate/utils.py:292: DuplicateColumnWarning: Column name "Code" already exists in Table. Column will be renamed to "Code_2".
/usr/local/lib/python2.7/site-packages/agate/utils.py:292: DuplicateColumnWarning: Column name "Num" already exists in Table. Column will be renamed to "Num_3".
/usr/local/lib/python2.7/site-packages/agate/utils.py:292: DuplicateColumnWarning: Column name "Code" already exists in Table. Column will be renamed to "Code_3".
/usr/local/lib/python2.7/site-packages/agate/utils.py:292: DuplicateColumnWarning: Column name "Num" already exists in Table. Column will be renamed to "Num_4".
/usr/local/lib/python2.7/site-packages/agate/utils.py:292: DuplicateColumnWarning: Column name "Code" already exists in Table. Column will be renamed to "Code_4".
/usr/local/lib/python2.7/site-packages/agate/utils.py:276: UnnamedColumnWarning: Column 26 has no name. Using "aa".
/usr/local/lib/python2.7/site-packages/agate/utils.py:276: UnnamedColumnWarning: Column 27 has no name. Using "bb".
/usr/local/lib/python2.7/site-packages/agate/utils.py:276: UnnamedColumnWarning: Column 28 has no name. Using "cc".
/usr/local/lib/python2.7/site-packages/agate/utils.py:276: UnnamedColumnWarning: Column 29 has no name. Using "dd".
/usr/local/lib/python2.7/site-packages/agate/utils.py:276: UnnamedColumnWarning: Column 30 has no name. Using "ee".
/usr/local/lib/python2.7/site-packages/agate/utils.py:276: UnnamedColumnWarning: Column 31 has no name. Using "ff".
/usr/local/lib/python2.7/site-packages/agate/utils.py:276: UnnamedColumnWarning: Column 32 has no name. Using "gg".
/usr/local/lib/python2.7/site-packages/agate/utils.py:276: UnnamedColumnWarning: Column 33 has no name. Using "hh".
/usr/local/lib/python2.7/site-packages/agate/utils.py:276: UnnamedColumnWarning: Column 34 has no name. Using "ii".
/usr/local/lib/python2.7/site-packages/agate/utils.py:276: UnnamedColumnWarning: Column 35 has no name. Using "jj".
/usr/local/lib/python2.7/site-packages/agate/utils.py:276: UnnamedColumnWarning: Column 36 has no name. Using "kk".
/usr/local/lib/python2.7/site-packages/agate/utils.py:276: UnnamedColumnWarning: Column 37 has no name. Using "ll".
/usr/local/lib/python2.7/site-packages/agate/utils.py:276: UnnamedColumnWarning: Column 38 has no name. Using "mm".
/usr/local/lib/python2.7/site-packages/agate/utils.py:276: UnnamedColumnWarning: Column 39 has no name. Using "nn".
/usr/local/lib/python2.7/site-packages/agate/utils.py:276: UnnamedColumnWarning: Column 40 has no name. Using "oo".
/usr/local/lib/python2.7/site-packages/agate/utils.py:276: UnnamedColumnWarning: Column 41 has no name. Using "pp".
/usr/local/lib/python2.7/site-packages/agate/utils.py:276: UnnamedColumnWarning: Column 42 has no name. Using "qq".
/usr/local/lib/python2.7/site-packages/agate/utils.py:276: UnnamedColumnWarning: Column 43 has no name. Using "rr".
/usr/local/lib/python2.7/site-packages/agate/utils.py:276: UnnamedColumnWarning: Column 44 has no name. Using "ss".
/usr/local/lib/python2.7/site-packages/agate/utils.py:276: UnnamedColumnWarning: Column 45 has no name. Using "tt".
